Workbook

Sheet Read Me
A1: The Hall of Echoing Mirrors - Economy Model
A2: Does the current design produce runs worth playing? v0.1, greybox.
A4: The question this answers
A5: A run that lasts 8 actions has no queue puzzle, however elegant the overflow rule is.
A6: A run that lasts 800 is a chore. This model finds where the numbers actually land.
A8: Sheets
A9: Parameters Every tunable number. Blue cells are yours; everything else is a formula.
A10: Build Comparison The four archetypes side by side: travel endurance and realm depth.
A11: Run Ledger A step-by-step simulation. Edit the Action and Hue columns to test a route.
A12: Health Checks Pass/fail on the design questions the model exists to answer.
A14: How to use it
A15: 1. Open Health Checks. Anything reading CHECK is a design problem, not a spreadsheet problem.
... A23: Gather has no diminishing returns modelled; set its vitality cost to 0 to see the infinite loop.

Sheet Parameters
A1: Parameters
A2: Blue cells are inputs.
A4: THE CLOCK
A5: Vitality maximum | B5: 100 | C5: The run ends when this hits zero
A6: Overflow multiplier | B6: 1 | C6: Vitality cost per point of unpayable pathos. 1.0 = full price
A8: POOLS
A9: Total pathos budget | B9: 700 | C9: Distributed across 7 pools on Build Comparison
A10: Pool capacity cap per hue | B10: 700 | C10: Ceiling a single pool can hold
A12: ACTION COSTS
A13: Hall traversal - per pool | B13: 15 | C13: Drawn from ALL SEVEN pools. The dominant cost
A14: Realm work - primary hue | B14: 8 | C14: A standard working in the realm's own hue
A15: Realm work - vitality paid | B15: 12 | C15: Burst: pay a working in vitality instead (Maroon)
A16: Gather - yield | B16: 20 | C16: Pathos returned to the target pool
A17: Gather - vitality cost | B17: 2 | C17: Set to 0 to demonstrate the infinite gather loop
A19: TIME
A20: Seconds per action | B20: 4 | C20: Average at 1x speed
A21: Target actions per run - low | B21: 30 | C21: Below this, the queue is too short to be a puzzle
A22: Target actions per run - high | B22: 90 | C22: Above this, planning becomes tedious
A24: WALL THRESHOLDS
A25: Magnitude wall requirement | B25: 400 | C25: Single-hue value needed. Spike territory
A26: Breadth wall requirement | B26: 60 | C26: Needed in 4+ hues AT ONCE. Balanced territory

Sheet Build Comparison
A1: Build Comparison
A2: Allocations are inputs (blue). Everything else is computed. Travel endurance assumes travel-only; realm depth assumes one hue is spent after arriving.
A4: ALLOCATION
A5: Build | B5: Amber | C5: Citrine | D5: Emerald | E5: Sapphire | F5: Iolite | G5: Amethyst | H5: Ruby | I5: Total | J5: Budget OK? | K5: Pays vitality?
A6: Balanced | B6: 100 | C6: 100 | D6: 100 | E6: 100 | F6: 100 | G6: 100 | H6: 100 | I6: =SUM(B6:H6) -> 700 | J6: =IF(I6<=Parameters!$B$9,"OK","OVER BUDGET") -> OK | K6: No
A7: Spike (Ruby) | B7: 10 | C7: 10 | D7: 10 | E7: 10 | F7: 10 | G7: 10 | H7: 640 | I7: =SUM(B7:H7) -> 700 | J7: =IF(I7<=Parameters!$B$9,"OK","OVER BUDGET") -> OK | K7: No
A8: Lopsided | B8: 250 | C8: 200 | D8: 150 | E8: 25 | F8: 25 | G8: 25 | H8: 25 | I8: =SUM(B8:H8) -> 700 | J8: =IF(I8<=Parameters!$B$9,"OK","OVER BUDGET") -> OK | K8: No
A9: Burst | B9: 100 | C9: 100 | D9: 100 | E9: 100 | F9: 100 | G9: 100 | H9: 100 | I9: =SUM(B9:H9) -> 700 | J9: =IF(I9<=Parameters!$B$9,"OK","OVER BUDGET") -> OK | K9: Yes
A12: TRAVEL ENDURANCE
A13: Vitality spent on each successive hall traversal. A pool that runs dry stops absorbing, so its share overflows to vitality.
A14: Build | B14: Trav 1 | C14: Trav 2 | D14: Trav 3 | E14: Trav 4 | F14: Trav 5 | G14: Trav 6 | H14: Trav 7 | I14: Trav 8 | J14: Cum. 1-8 | K14: Max traversals
A15: =A6 -> Balanced | B15: =(MAX(0,Parameters!$B$13-MIN(Parameters!$B$13,MAX(0,B6-Parameters!$B$13*0)))+MAX(0,Parameters!$B$13-MIN(Parameters!$B$13,MAX(0,C6-Parameters!$B$13*0)))+MAX(0,Parameters!$B$13-MIN(Parameters!$B$13,MAX(0,D6-Parameters!$B$13*0)))+MAX(0,Parameters!$B$13-MIN(Parameters!$B$13,MAX(0,E6-Parameters!$B$13*0)))+MAX(0,Parameters!$B$13-MIN(Parameters!$B$13,MAX(0,F6-Parameters!$B$13*0)))+MAX(0,Parameters!$B$13-MIN(Parameters!$B$13,MAX(0,G6-Parameters!$B$13*0)))+MAX(0,Parameters!$B$13-MIN(Parameters!$B$13,MAX(0,H6-Parameters!$B$13*0))))*Parameters!$B$6 -> 0 | C15: =(MAX(0,Parameters!$B$13-MIN(Parameters!$B$13,MAX(0,B6-Parameters!$B$13*1)))+MAX(0,Parameters!$B$13-MIN(Parameters!$B$13,MAX(0,C6-Parameters!$B$13*1)))+MAX(0,Parameters!$B$13-MIN(Parameters!$B$13,MAX(0,D6-Parameters!$B$13*1)))+MAX(0,Parameters!$B$13-MIN(Parameters!$B$13,MAX(0,E6-Parameters!$B$13*1)))+MAX(0,Parameters!$B$13-MIN(Parameters!$B$13,MAX(0,F6-Parameters!$B$13*1)))+MAX(0,Parameters!$B$13-MIN(Parameters!$B$13,MAX(0,G6-Parameters!$B$13*1)))+MAX(0,Parameters!$B$13-MIN(Parameters!$B$13,MAX(0,H6-Parameters!$B$13*1))))*Parameters!$B$6 -> 0 | D15: =(MAX(0,Parameters!$B$13-MIN(Parameters!$B$13,MAX(0,B6-Parameters!$B$13*2)))+MAX(0,Parameters!$B$13-MIN(Parameters!$B$13,MAX(0,C6-Parameters!$B$13*2)))+MAX(0,Parameters!$B$13-MIN(Parameters!$B$13,MAX(0,D6-Parameters!$B$13*2)))+MAX(0,Parameters!$B$13-MIN(Parameters!$B$13,MAX(0,E6-Parameters!$B$13*2)))+MAX(0,Parameters!$B$13-MIN(Parameters!$B$13,MAX(0,F6-Parameters!$B$13*2)))+MAX(0,Parameters!$B$13-MIN(Parameters!$B$13,MAX(0,G6-Parameters!$B$13*2)))+MAX(0,Parameters!$B$13-MIN(Parameters!$B$13,MAX(0,H6-Parameters!$B$13*2))))*Parameters!$B$6 -> 0 | E15: =(MAX(0,Parameters!$B$13-MIN(Parameters!$B$13,MAX(0,B6-Parameters!$B$13*3)))+MAX(0,Parameters!$B$13-MIN(Parameters!$B$13,MAX(0,C6-Parameters!$B$13*3)))+MAX(0,Parameters!$B$13-MIN(Parameters!$B$13,MAX(0,D6-Parameters!$B$13*3)))+MAX(0,Parameters!$B$13-MIN(Parameters!$B$13,MAX(0,E6-Parameters!$B$13*3)))+MAX(0,Parameters!$B$13-MIN(Parameters!$B$13,MAX(0,F6-Parameters!$B$13*3)))+MAX(0,Parameters!$B$13-MIN(Parameters!$B$13,MAX(0,G6-Parameters!$B$13*3)))+MAX(0,Parameters!$B$13-MIN(Parameters!$B$13,MAX(0,H6-Parameters!$B$13*3))))*Parameters!$B$6 -> 0 | F15: =(MAX(0,Parameters!$B$13-MIN(Parameters!$B$13,MAX(0,B6-Parameters!$B$13*4)))+MAX(0,Parameters!$B$13-MIN(Parameters!$B$13,MAX(0,C6-Parameters!$B$13*4)))+MAX(0,Parameters!$B$13-MIN(Parameters!$B$13,MAX(0,D6-Parameters!$B$13*4)))+MAX(0,Parameters!$B$13-MIN(Parameters!$B$13,MAX(0,E6-Parameters!$B$13*4)))+MAX(0,Parameters!$B$13-MIN(Parameters!$B$13,MAX(0,F6-Parameters!$B$13*4)))+MAX(0,Parameters!$B$13-MIN(Parameters!$B$13,MAX(0,G6-Parameters!$B$13*4)))+MAX(0,Parameters!$B$13-MIN(Parameters!$B$13,MAX(0,H6-Parameters!$B$13*4))))*Parameters!$B$6 -> 0 | G15: =(MAX(0,Parameters!$B$13-MIN(Parameters!$B$13,MAX(0,B6-Parameters!$B$13*5)))+MAX(0,Parameters!$B$13-MIN(Parameters!$B$13,MAX(0,C6-Parameters!$B$13*5)))+MAX(0,Parameters!$B$13-MIN(Parameters!$B$13,MAX(0,D6-Parameters!$B$13*5)))+MAX(0,Parameters!$B$13-MIN(Parameters!$B$13,MAX(0,E6-Parameters!$B$13*5)))+MAX(0,Parameters!$B$13-MIN(Parameters!$B$13,MAX(0,F6-Parameters!$B$13*5)))+MAX(0,Parameters!$B$13-MIN(Parameters!$B$13,MAX(0,G6-Parameters!$B$13*5)))+MAX(0,Parameters!$B$13-MIN(Parameters!$B$13,MAX(0,H6-Parameters!$B$13*5))))*Parameters!$B$6 -> 0 | H15: =(MAX(0,Parameters!$B$13-MIN(Parameters!$B$13,MAX(0,B6-Parameters!$B$13*6)))+MAX(0,Parameters!$B$13-MIN(Parameters!$B$13,MAX(0,C6-Parameters!$B$13*6)))+MAX(0,Parameters!$B$13-MIN(Parameters!$B$13,MAX(0,D6-Parameters!$B$13*6)))+MAX(0,Parameters!$B$13-MIN(Parameters!$B$13,MAX(0,E6-Parameters!$B$13*6)))+MAX(0,Parameters!$B$13-MIN(Parameters!$B$13,MAX(0,F6-Parameters!$B$13*6)))+MAX(0,Parameters!$B$13-MIN(Parameters!$B$13,MAX(0,G6-Parameters!$B$13*6)))+MAX(0,Parameters!$B$13-MIN(Parameters!$B$13,MAX(0,H6-Parameters!$B$13*6))))*Parameters!$B$6 -> 35 | I15: =(MAX(0,Parameters!$B$13-MIN(Parameters!$B$13,MAX(0,B6-Parameters!$B$13*7)))+MAX(0,Parameters!$B$13-MIN(Parameters!$B$13,MAX(0,C6-Parameters!$B$13*7)))+MAX(0,Parameters!$B$13-MIN(Parameters!$B$13,MAX(0,D6-Parameters!$B$13*7)))+MAX(0,Parameters!$B$13-MIN(Parameters!$B$13,MAX(0,E6-Parameters!$B$13*7)))+MAX(0,Parameters!$B$13-MIN(Parameters!$B$13,MAX(0,F6-Parameters!$B$13*7)))+MAX(0,Parameters!$B$13-MIN(Parameters!$B$13,MAX(0,G6-Parameters!$B$13*7)))+MAX(0,Parameters!$B$13-MIN(Parameters!$B$13,MAX(0,H6-Parameters!$B$13*7))))*Parameters!$B$6 -> 105 | J15: =SUM(B15:I15) -> 140 | K15: =COUNTIF(B15:I15,"<"&Parameters!$B$5) -> 7
A16: =A7 -> Spike (Ruby) | B16: =(MAX(0,Parameters!$B$13-MIN(Parameters!$B$13,MAX(0,B7-Parameters!$B$13*0)))+MAX(0,Parameters!$B$13-MIN(Parameters!$B$13,MAX(0,C7-Parameters!$B$13*0)))+MAX(0,Parameters!$B$13-MIN(Parameters!$B$13,MAX(0,D7-Parameters!$B$13*0)))+MAX(0,Parameters!$B$13-MIN(Parameters!$B$13,MAX(0,E7-Parameters!$B$13*0)))+MAX(0,Parameters!$B$13-MIN(Parameters!$B$13,MAX(0,F7-Parameters!$B$13*0)))+MAX(0,Parameters!$B$13-MIN(Parameters!$B$13,MAX(0,G7-Parameters!$B$13*0)))+MAX(0,Parameters!$B$13-MIN(Parameters!$B$13,MAX(0,H7-Parameters!$B$13*0))))*Parameters!$B$6 -> 30 | C16: =(MAX(0,Parameters!$B$13-MIN(Parameters!$B$13,MAX(0,B7-Parameters!$B$13*1)))+MAX(0,Parameters!$B$13-MIN(Parameters!$B$13,MAX(0,C7-Parameters!$B$13*1)))+MAX(0,Parameters!$B$13-MIN(Parameters!$B$13,MAX(0,D7-Parameters!$B$13*1)))+MAX(0,Parameters!$B$13-MIN(Parameters!$B$13,MAX(0,E7-Parameters!$B$13*1)))+MAX(0,Parameters!$B$13-MIN(Parameters!$B$13,MAX(0,F7-Parameters!$B$13*1)))+MAX(0,Parameters!$B$13-MIN(Parameters!$B$13,MAX(0,G7-Parameters!$B$13*1)))+MAX(0,Parameters!$B$13-MIN(Parameters!$B$13,MAX(0,H7-Parameters!$B$13*1))))*Parameters!$B$6 -> 90 | D16: =(MAX(0,Parameters!$B$13-MIN(Parameters!$B$13,MAX(0,B7-Parameters!$B$13*2)))+MAX(0,Parameters!$B$13-MIN(Parameters!$B$13,MAX(0,C7-Parameters!$B$13*2)))+MAX(0,Parameters!$B$13-MIN(Parameters!$B$13,MAX(0,D7-Parameters!$B$13*2)))+MAX(0,Parameters!$B$13-MIN(Parameters!$B$13,MAX(0,E7-Parameters!$B$13*2)))+MAX(0,Parameters!$B$13-MIN(Parameters!$B$13,MAX(0,F7-Parameters!$B$13*2)))+MAX(0,Parameters!$B$13-MIN(Parameters!$B$13,MAX(0,G7-Parameters!$B$13*2)))+MAX(0,Parameters!$B$13-MIN(Parameters!$B$13,MAX(0,H7-Parameters!$B$13*2))))*Parameters!$B$6 -> 90 | E16: =(MAX(0,Parameters!$B$13-MIN(Parameters!$B$13,MAX(0,B7-Parameters!$B$13*3)))+MAX(0,Parameters!$B$13-MIN(Parameters!$B$13,MAX(0,C7-Parameters!$B$13*3)))+MAX(0,Parameters!$B$13-MIN(Parameters!$B$13,MAX(0,D7-Parameters!$B$13*3)))+MAX(0,Parameters!$B$13-MIN(Parameters!$B$13,MAX(0,E7-Parameters!$B$13*3)))+MAX(0,Parameters!$B$13-MIN(Parameters!$B$13,MAX(0,F7-Parameters!$B$13*3)))+MAX(0,Parameters!$B$13-MIN(Parameters!$B$13,MAX(0,G7-Parameters!$B$13*3)))+MAX(0,Parameters!$B$13-MIN(Parameters!$B$13,MAX(0,H7-Parameters!$B$13*3))))*Parameters!$B$6 -> 90 | F16: =(MAX(0,Parameters!$B$13-MIN(Parameters!$B$13,MAX(0,B7-Parameters!$B$13*4)))+MAX(0,Parameters!$B$13-MIN(Parameters!$B$13,MAX(0,C7-Parameters!$B$13*4)))+MAX(0,Parameters!$B$13-MIN(Parameters!$B$13,MAX(0,D7-Parameters!$B$13*4)))+MAX(0,Parameters!$B$13-MIN(Parameters!$B$13,MAX(0,E7-Parameters!$B$13*4)))+MAX(0,Parameters!$B$13-MIN(Parameters!$B$13,MAX(0,F7-Parameters!$B$13*4)))+MAX(0,Parameters!$B$13-MIN(Parameters!$B$13,MAX(0,G7-Parameters!$B$13*4)))+MAX(0,Parameters!$B$13-MIN(Parameters!$B$13,MAX(0,H7-Parameters!$B$13*4))))*Parameters!$B$6 -> 90 | G16: =(MAX(0,Parameters!$B$13-MIN(Parameters!$B$13,MAX(0,B7-Parameters!$B$13*5)))+MAX(0,Parameters!$B$13-MIN(Parameters!$B$13,MAX(0,C7-Parameters!$B$13*5)))+MAX(0,Parameters!$B$13-MIN(Parameters!$B$13,MAX(0,D7-Parameters!$B$13*5)))+MAX(0,Parameters!$B$13-MIN(Parameters!$B$13,MAX(0,E7-Parameters!$B$13*5)))+MAX(0,Parameters!$B$13-MIN(Parameters!$B$13,MAX(0,F7-Parameters!$B$13*5)))+MAX(0,Parameters!$B$13-MIN(Parameters!$B$13,MAX(0,G7-Parameters!$B$13*5)))+MAX(0,Parameters!$B$13-MIN(Parameters!$B$13,MAX(0,H7-Parameters!$B$13*5))))*Parameters!$B$6 -> 90 | H16: =(MAX(0,Parameters!$B$13-MIN(Parameters!$B$13,MAX(0,B7-Parameters!$B$13*6)))+MAX(0,Parameters!$B$13-MIN(Parameters!$B$13,MAX(0,C7-Parameters!$B$13*6)))+MAX(0,Parameters!$B$13-MIN(Parameters!$B$13,MAX(0,D7-Parameters!$B$13*6)))+MAX(0,Parameters!$B$13-MIN(Parameters!$B$13,MAX(0,E7-Parameters!$B$13*6)))+MAX(0,Parameters!$B$13-MIN(Parameters!$B$13,MAX(0,F7-Parameters!$B$13*6)))+MAX(0,Parameters!$B$13-MIN(Parameters!$B$13,MAX(0,G7-Parameters!$B$13*6)))+MAX(0,Parameters!$B$13-MIN(Parameters!$B$13,MAX(0,H7-Parameters!$B$13*6))))*Parameters!$B$6 -> 90 | I16: =(MAX(0,Parameters!$B$13-MIN(Parameters!$B$13,MAX(0,B7-Parameters!$B$13*7)))+MAX(0,Parameters!$B$13-MIN(Parameters!$B$13,MAX(0,C7-Parameters!$B$13*7)))+MAX(0,Parameters!$B$13-MIN(Parameters!$B$13,MAX(0,D7-Parameters!$B$13*7)))+MAX(0,Parameters!$B$13-MIN(Parameters!$B$13,MAX(0,E7-Parameters!$B$13*7)))+MAX(0,Parameters!$B$13-MIN(Parameters!$B$13,MAX(0,F7-Parameters!$B$13*7)))+MAX(0,Parameters!$B$13-MIN(Parameters!$B$13,MAX(0,G7-Parameters!$B$13*7)))+MAX(0,Parameters!$B$13-MIN(Parameters!$B$13,MAX(0,H7-Parameters!$B$13*7))))*Parameters!$B$6 -> 90 | J16: =SUM(B16:I16) -> 660 | K16: =COUNTIF(B16:I16,"<"&Parameters!$B$5) -> 8
A17: =A8 -> Lopsided | B17: =(MAX(0,Parameters!$B$13-MIN(Parameters!$B$13,MAX(0,B8-Parameters!$B$13*0)))+MAX(0,Parameters!$B$13-MIN(Parameters!$B$13,MAX(0,C8-Parameters!$B$13*0)))+MAX(0,Parameters!$B$13-MIN(Parameters!$B$13,MAX(0,D8-Parameters!$B$13*0)))+MAX(0,Parameters!$B$13-MIN(Parameters!$B$13,MAX(0,E8-Parameters!$B$13*0)))+MAX(0,Parameters!$B$13-MIN(Parameters!$B$13,MAX(0,F8-Parameters!$B$13*0)))+MAX(0,Parameters!$B$13-MIN(Parameters!$B$13,MAX(0,G8-Parameters!$B$13*0)))+MAX(0,Parameters!$B$13-MIN(Parameters!$B$13,MAX(0,H8-Parameters!$B$13*0))))*Parameters!$B$6 -> 0 | C17: =(MAX(0,Parameters!$B$13-MIN(Parameters!$B$13,MAX(0,B8-Parameters!$B$13*1)))+MAX(0,Parameters!$B$13-MIN(Parameters!$B$13,MAX(0,C8-Parameters!$B$13*1)))+MAX(0,Parameters!$B$13-MIN(Parameters!$B$13,MAX(0,D8-Parameters!$B$13*1)))+MAX(0,Parameters!$B$13-MIN(Parameters!$B$13,MAX(0,E8-Parameters!$B$13*1)))+MAX(0,Parameters!$B$13-MIN(Parameters!$B$13,MAX(0,F8-Parameters!$B$13*1)))+MAX(0,Parameters!$B$13-MIN(Parameters!$B$13,MAX(0,G8-Parameters!$B$13*1)))+MAX(0,Parameters!$B$13-MIN(Parameters!$B$13,MAX(0,H8-Parameters!$B$13*1))))*Parameters!$B$6 -> 20 | D17: =(MAX(0,Parameters!$B$13-MIN(Parameters!$B$13,MAX(0,B8-Parameters!$B$13*2)))+MAX(0,Parameters!$B$13-MIN(Parameters!$B$13,MAX(0,C8-Parameters!$B$13*2)))+MAX(0,Parameters!$B$13-MIN(Parameters!$B$13,MAX(0,D8-Parameters!$B$13*2)))+MAX(0,Parameters!$B$13-MIN(Parameters!$B$13,MAX(0,E8-Parameters!$B$13*2)))+MAX(0,Parameters!$B$13-MIN(Parameters!$B$13,MAX(0,F8-Parameters!$B$13*2)))+MAX(0,Parameters!$B$13-MIN(Parameters!$B$13,MAX(0,G8-Parameters!$B$13*2)))+MAX(0,Parameters!$B$13-MIN(Parameters!$B$13,MAX(0,H8-Parameters!$B$13*2))))*Parameters!$B$6 -> 60 | E17: =(MAX(0,Parameters!$B$13-MIN(Parameters!$B$13,MAX(0,B8-Parameters!$B$13*3)))+MAX(0,Parameters!$B$13-MIN(Parameters!$B$13,MAX(0,C8-Parameters!$B$13*3)))+MAX(0,Parameters!$B$13-MIN(Parameters!$B$13,MAX(0,D8-Parameters!$B$13*3)))+MAX(0,Parameters!$B$13-MIN(Parameters!$B$13,MAX(0,E8-Parameters!$B$13*3)))+MAX(0,Parameters!$B$13-MIN(Parameters!$B$13,MAX(0,F8-Parameters!$B$13*3)))+MAX(0,Parameters!$B$13-MIN(Parameters!$B$13,MAX(0,G8-Parameters!$B$13*3)))+MAX(0,Parameters!$B$13-MIN(Parameters!$B$13,MAX(0,H8-Parameters!$B$13*3))))*Parameters!$B$6 -> 60 | F17: =(MAX(0,Parameters!$B$13-MIN(Parameters!$B$13,MAX(0,B8-Parameters!$B$13*4)))+MAX(0,Parameters!$B$13-MIN(Parameters!$B$13,MAX(0,C8-Parameters!$B$13*4)))+MAX(0,Parameters!$B$13-MIN(Parameters!$B$13,MAX(0,D8-Parameters!$B$13*4)))+MAX(0,Parameters!$B$13-MIN(Parameters!$B$13,MAX(0,E8-Parameters!$B$13*4)))+MAX(0,Parameters!$B$13-MIN(Parameters!$B$13,MAX(0,F8-Parameters!$B$13*4)))+MAX(0,Parameters!$B$13-MIN(Parameters!$B$13,MAX(0,G8-Parameters!$B$13*4)))+MAX(0,Parameters!$B$13-MIN(Parameters!$B$13,MAX(0,H8-Parameters!$B$13*4))))*Parameters!$B$6 -> 60 | G17: =(MAX(0,Parameters!$B$13-MIN(Parameters!$B$13,MAX(0,B8-Parameters!$B$13*5)))+MAX(0,Parameters!$B$13-MIN(Parameters!$B$13,MAX(0,C8-Parameters!$B$13*5)))+MAX(0,Parameters!$B$13-MIN(Parameters!$B$13,MAX(0,D8-Parameters!$B$13*5)))+MAX(0,Parameters!$B$13-MIN(Parameters!$B$13,MAX(0,E8-Parameters!$B$13*5)))+MAX(0,Parameters!$B$13-MIN(Parameters!$B$13,MAX(0,F8-Parameters!$B$13*5)))+MAX(0,Parameters!$B$13-MIN(Parameters!$B$13,MAX(0,G8-Parameters!$B$13*5)))+MAX(0,Parameters!$B$13-MIN(Parameters!$B$13,MAX(0,H8-Parameters!$B$13*5))))*Parameters!$B$6 -> 60 | H17: =(MAX(0,Parameters!$B$13-MIN(Parameters!$B$13,MAX(0,B8-Parameters!$B$13*6)))+MAX(0,Parameters!$B$13-MIN(Parameters!$B$13,MAX(0,C8-Parameters!$B$13*6)))+MAX(0,Parameters!$B$13-MIN(Parameters!$B$13,MAX(0,D8-Parameters!$B$13*6)))+MAX(0,Parameters!$B$13-MIN(Parameters!$B$13,MAX(0,E8-Parameters!$B$13*6)))+MAX(0,Parameters!$B$13-MIN(Parameters!$B$13,MAX(0,F8-Parameters!$B$13*6)))+MAX(0,Parameters!$B$13-MIN(Parameters!$B$13,MAX(0,G8-Parameters!$B$13*6)))+MAX(0,Parameters!$B$13-MIN(Parameters!$B$13,MAX(0,H8-Parameters!$B$13*6))))*Parameters!$B$6 -> 60 | I17: =(MAX(0,Parameters!$B$13-MIN(Parameters!$B$13,MAX(0,B8-Parameters!$B$13*7)))+MAX(0,Parameters!$B$13-MIN(Parameters!$B$13,MAX(0,C8-Parameters!$B$13*7)))+MAX(0,Parameters!$B$13-MIN(Parameters!$B$13,MAX(0,D8-Parameters!$B$13*7)))+MAX(0,Parameters!$B$13-MIN(Parameters!$B$13,MAX(0,E8-Parameters!$B$13*7)))+MAX(0,Parameters!$B$13-MIN(Parameters!$B$13,MAX(0,F8-Parameters!$B$13*7)))+MAX(0,Parameters!$B$13-MIN(Parameters!$B$13,MAX(0,G8-Parameters!$B$13*7)))+MAX(0,Parameters!$B$13-MIN(Parameters!$B$13,MAX(0,H8-Parameters!$B$13*7))))*Parameters!$B$6 -> 60 | J17: =SUM(B17:I17) -> 380 | K17: =COUNTIF(B17:I17,"<"&Parameters!$B$5) -> 8
A18: =A9 -> Burst | B18: =(MAX(0,Parameters!$B$13-MIN(Parameters!$B$13,MAX(0,B9-Parameters!$B$13*0)))+MAX(0,Parameters!$B$13-MIN(Parameters!$B$13,MAX(0,C9-Parameters!$B$13*0)))+MAX(0,Parameters!$B$13-MIN(Parameters!$B$13,MAX(0,D9-Parameters!$B$13*0)))+MAX(0,Parameters!$B$13-MIN(Parameters!$B$13,MAX(0,E9-Parameters!$B$13*0)))+MAX(0,Parameters!$B$13-MIN(Parameters!$B$13,MAX(0,F9-Parameters!$B$13*0)))+MAX(0,Parameters!$B$13-MIN(Parameters!$B$13,MAX(0,G9-Parameters!$B$13*0)))+MAX(0,Parameters!$B$13-MIN(Parameters!$B$13,MAX(0,H9-Parameters!$B$13*0))))*Parameters!$B$6 -> 0 | C18: =(MAX(0,Parameters!$B$13-MIN(Parameters!$B$13,MAX(0,B9-Parameters!$B$13*1)))+MAX(0,Parameters!$B$13-MIN(Parameters!$B$13,MAX(0,C9-Parameters!$B$13*1)))+MAX(0,Parameters!$B$13-MIN(Parameters!$B$13,MAX(0,D9-Parameters!$B$13*1)))+MAX(0,Parameters!$B$13-MIN(Parameters!$B$13,MAX(0,E9-Parameters!$B$13*1)))+MAX(0,Parameters!$B$13-MIN(Parameters!$B$13,MAX(0,F9-Parameters!$B$13*1)))+MAX(0,Parameters!$B$13-MIN(Parameters!$B$13,MAX(0,G9-Parameters!$B$13*1)))+MAX(0,Parameters!$B$13-MIN(Parameters!$B$13,MAX(0,H9-Parameters!$B$13*1))))*Parameters!$B$6 -> 0 | D18: =(MAX(0,Parameters!$B$13-MIN(Parameters!$B$13,MAX(0,B9-Parameters!$B$13*2)))+MAX(0,Parameters!$B$13-MIN(Parameters!$B$13,MAX(0,C9-Parameters!$B$13*2)))+MAX(0,Parameters!$B$13-MIN(Parameters!$B$13,MAX(0,D9-Parameters!$B$13*2)))+MAX(0,Parameters!$B$13-MIN(Parameters!$B$13,MAX(0,E9-Parameters!$B$13*2)))+MAX(0,Parameters!$B$13-MIN(Parameters!$B$13,MAX(0,F9-Parameters!$B$13*2)))+MAX(0,Parameters!$B$13-MIN(Parameters!$B$13,MAX(0,G9-Parameters!$B$13*2)))+MAX(0,Parameters!$B$13-MIN(Parameters!$B$13,MAX(0,H9-Parameters!$B$13*2))))*Parameters!$B$6 -> 0 | E18: =(MAX(0,Parameters!$B$13-MIN(Parameters!$B$13,MAX(0,B9-Parameters!$B$13*3)))+MAX(0,Parameters!$B$13-MIN(Parameters!$B$13,MAX(0,C9-Parameters!$B$13*3)))+MAX(0,Parameters!$B$13-MIN(Parameters!$B$13,MAX(0,D9-Parameters!$B$13*3)))+MAX(0,Parameters!$B$13-MIN(Parameters!$B$13,MAX(0,E9-Parameters!$B$13*3)))+MAX(0,Parameters!$B$13-MIN(Parameters!$B$13,MAX(0,F9-Parameters!$B$13*3)))+MAX(0,Parameters!$B$13-MIN(Parameters!$B$13,MAX(0,G9-Parameters!$B$13*3)))+MAX(0,Parameters!$B$13-MIN(Parameters!$B$13,MAX(0,H9-Parameters!$B$13*3))))*Parameters!$B$6 -> 0 | F18: =(MAX(0,Parameters!$B$13-MIN(Parameters!$B$13,MAX(0,B9-Parameters!$B$13*4)))+MAX(0,Parameters!$B$13-MIN(Parameters!$B$13,MAX(0,C9-Parameters!$B$13*4)))+MAX(0,Parameters!$B$13-MIN(Parameters!$B$13,MAX(0,D9-Parameters!$B$13*4)))+MAX(0,Parameters!$B$13-MIN(Parameters!$B$13,MAX(0,E9-Parameters!$B$13*4)))+MAX(0,Parameters!$B$13-MIN(Parameters!$B$13,MAX(0,F9-Parameters!$B$13*4)))+MAX(0,Parameters!$B$13-MIN(Parameters!$B$13,MAX(0,G9-Parameters!$B$13*4)))+MAX(0,Parameters!$B$13-MIN(Parameters!$B$13,MAX(0,H9-Parameters!$B$13*4))))*Parameters!$B$6 -> 0 | G18: =(MAX(0,Parameters!$B$13-MIN(Parameters!$B$13,MAX(0,B9-Parameters!$B$13*5)))+MAX(0,Parameters!$B$13-MIN(Parameters!$B$13,MAX(0,C9-Parameters!$B$13*5)))+MAX(0,Parameters!$B$13-MIN(Parameters!$B$13,MAX(0,D9-Parameters!$B$13*5)))+MAX(0,Parameters!$B$13-MIN(Parameters!$B$13,MAX(0,E9-Parameters!$B$13*5)))+MAX(0,Parameters!$B$13-MIN(Parameters!$B$13,MAX(0,F9-Parameters!$B$13*5)))+MAX(0,Parameters!$B$13-MIN(Parameters!$B$13,MAX(0,G9-Parameters!$B$13*5)))+MAX(0,Parameters!$B$13-MIN(Parameters!$B$13,MAX(0,H9-Parameters!$B$13*5))))*Parameters!$B$6 -> 0 | H18: =(MAX(0,Parameters!$B$13-MIN(Parameters!$B$13,MAX(0,B9-Parameters!$B$13*6)))+MAX(0,Parameters!$B$13-MIN(Parameters!$B$13,MAX(0,C9-Parameters!$B$13*6)))+MAX(0,Parameters!$B$13-MIN(Parameters!$B$13,MAX(0,D9-Parameters!$B$13*6)))+MAX(0,Parameters!$B$13-MIN(Parameters!$B$13,MAX(0,E9-Parameters!$B$13*6)))+MAX(0,Parameters!$B$13-MIN(Parameters!$B$13,MAX(0,F9-Parameters!$B$13*6)))+MAX(0,Parameters!$B$13-MIN(Parameters!$B$13,MAX(0,G9-Parameters!$B$13*6)))+MAX(0,Parameters!$B$13-MIN(Parameters!$B$13,MAX(0,H9-Parameters!$B$13*6))))*Parameters!$B$6 -> 35 | I18: =(MAX(0,Parameters!$B$13-MIN(Parameters!$B$13,MAX(0,B9-Parameters!$B$13*7)))+MAX(0,Parameters!$B$13-MIN(Parameters!$B$13,MAX(0,C9-Parameters!$B$13*7)))+MAX(0,Parameters!$B$13-MIN(Parameters!$B$13,MAX(0,D9-Parameters!$B$13*7)))+MAX(0,Parameters!$B$13-MIN(Parameters!$B$13,MAX(0,E9-Parameters!$B$13*7)))+MAX(0,Parameters!$B$13-MIN(Parameters!$B$13,MAX(0,F9-Parameters!$B$13*7)))+MAX(0,Parameters!$B$13-MIN(Parameters!$B$13,MAX(0,G9-Parameters!$B$13*7)))+MAX(0,Parameters!$B$13-MIN(Parameters!$B$13,MAX(0,H9-Parameters!$B$13*7))))*Parameters!$B$6 -> 105 | J18: =SUM(B18:I18) -> 140 | K18: =COUNTIF(B18:I18,"<"&Parameters!$B$5) -> 7
A20: Max traversals counts how many single traversals cost less than full vitality. Rough guide, not cumulative.
A22: REALM DEPTH
A23: After arriving, how many workings can be cast in the strongest hue before that pool is dry.
A24: Build | B24: Strongest pool | C24: After 1 traversal | D24: Workings available | E24: After 2 traversals | F24: Workings available | G24: Magnitude wall? | H24: Breadth wall?
A25: =A6 -> Balanced | B25: =MAX(B6:H6) -> 100 | C25: =MAX(0,B25-Parameters!$B$13) -> 85 | D25: =ROUNDDOWN(C25/Parameters!$B$14,0) -> 10 | E25: =MAX(0,B25-Parameters!$B$13*2) -> 70 | F25: =ROUNDDOWN(E25/Parameters!$B$14,0) -> 8 | G25: =IF(B25>=Parameters!$B$25,"PASS","fail") -> fail | H25: =IF(COUNTIF(B6:H6,">="&Parameters!$B$26)>=4,"PASS","fail") -> PASS
A26: =A7 -> Spike (Ruby) | B26: =MAX(B7:H7) -> 640 | C26: =MAX(0,B26-Parameters!$B$13) -> 625 | D26: =ROUNDDOWN(C26/Parameters!$B$14,0) -> 78 | E26: =MAX(0,B26-Parameters!$B$13*2) -> 610 | F26: =ROUNDDOWN(E26/Parameters!$B$14,0) -> 76 | G26: =IF(B26>=Parameters!$B$25,"PASS","fail") -> PASS | H26: =IF(COUNTIF(B7:H7,">="&Parameters!$B$26)>=4,"PASS","fail") -> fail
A27: =A8 -> Lopsided | B27: =MAX(B8:H8) -> 250 | C27: =MAX(0,B27-Parameters!$B$13) -> 235 | D27: =ROUNDDOWN(C27/Parameters!$B$14,0) -> 29 | E27: =MAX(0,B27-Parameters!$B$13*2) -> 220 | F27: =ROUNDDOWN(E27/Parameters!$B$14,0) -> 27 | G27: =IF(B27>=Parameters!$B$25,"PASS","fail") -> fail | H27: =IF(COUNTIF(B8:H8,">="&Parameters!$B$26)>=4,"PASS","fail") -> fail
A28: =A9 -> Burst | B28: =MAX(B9:H9) -> 100 | C28: =MAX(0,B28-Parameters!$B$13) -> 85 | D28: =ROUNDDOWN(C28/Parameters!$B$14,0) -> 10 | E28: =MAX(0,B28-Parameters!$B$13*2) -> 70 | F28: =ROUNDDOWN(E28/Parameters!$B$14,0) -> 8 | G28: =IF(B28>=Parameters!$B$25,"PASS","fail") -> fail | H28: =IF(COUNTIF(B9:H9,">="&Parameters!$B$26)>=4,"PASS","fail") -> PASS

Sheet Run Ledger
A1: Run Ledger
A2: One run, step by step. Edit column B (Travel / Work / Gather) and column C (hue 1-7) to test a route. Row 6 is the starting state - edit it or link it to a build.
A4: Starting pools | B4: =IF(TRUE(),"Edit row 6 directly, or paste a build's allocation into D6:J6","") -> Edit row 6 directly, or paste a build's allocation into D6:J6
A5: Step | B5: Action | C5: Hue | D5: Amber | E5: Citrine | F5: Emerald | G5: Sapphire | H5: Iolite | I5: Amethyst | J5: Ruby | K5: Vitality | L5: Overflow | M5: State | O5: RUN SUMMARY
A6: 0 | B6: START | D6: ='Build Comparison'!B$6 -> 100 | E6: ='Build Comparison'!C$6 -> 100 | F6: ='Build Comparison'!D$6 -> 100 | G6: ='Build Comparison'!E$6 -> 100 | H6: ='Build Comparison'!F$6 -> 100 | I6: ='Build Comparison'!G$6 -> 100 | J6: ='Build Comparison'!H$6 -> 100 | K6: =Parameters!$B$5 -> 100 | L6: 0 | M6: alive | O6: Actions completed | P6: =COUNTIF(M7:M51,"alive") -> 33
A7: 1 | B7: Travel | D7: =IF($K6<=0,D6,IF($B7="Travel",MAX(0,D6-Parameters!$B$13),IF(AND($B7="Work",$C7=1),MAX(0,D6-Parameters!$B$14),IF(AND($B7="Gather",$C7=1),MIN(Parameters!$B$10,D6+Parameters!$B$16),D6)))) -> 85 | E7: =IF($K6<=0,E6,IF($B7="Travel",MAX(0,E6-Parameters!$B$13),IF(AND($B7="Work",$C7=2),MAX(0,E6-Parameters!$B$14),IF(AND($B7="Gather",$C7=2),MIN(Parameters!$B$10,E6+Parameters!$B$16),E6)))) -> 85 | F7: =IF($K6<=0,F6,IF($B7="Travel",MAX(0,F6-Parameters!$B$13),IF(AND($B7="Work",$C7=3),MAX(0,F6-Parameters!$B$14),IF(AND($B7="Gather",$C7=3),MIN(Parameters!$B$10,F6+Parameters!$B$16),F6)))) -> 85 | G7: =IF($K6<=0,G6,IF($B7="Travel",MAX(0,G6-Parameters!$B$13),IF(AND($B7="Work",$C7=4),MAX(0,G6-Parameters!$B$14),IF(AND($B7="Gather",$C7=4),MIN(Parameters!$B$10,G6+Parameters!$B$16),G6)))) -> 85 | H7: =IF($K6<=0,H6,IF($B7="Travel",MAX(0,H6-Parameters!$B$13),IF(AND($B7="Work",$C7=5),MAX(0,H6-Parameters!$B$14),IF(AND($B7="Gather",$C7=5),MIN(Parameters!$B$10,H6+Parameters!$B$16),H6)))) -> 85 | I7: =IF($K6<=0,I6,IF($B7="Travel",MAX(0,I6-Parameters!$B$13),IF(AND($B7="Work",$C7=6),MAX(0,I6-Parameters!$B$14),IF(AND($B7="Gather",$C7=6),MIN(Parameters!$B$10,I6+Parameters!$B$16),I6)))) -> 85 | J7: =IF($K6<=0,J6,IF($B7="Travel",MAX(0,J6-Parameters!$B$13),IF(AND($B7="Work",$C7=7),MAX(0,J6-Parameters!$B$14),IF(AND($B7="Gather",$C7=7),MIN(Parameters!$B$10,J6+Parameters!$B$16),J6)))) -> 85 | K7: =IF($K6<=0,0,MAX(0,K6-L7*Parameters!$B$6-IF($B7="Gather",Parameters!$B$17,0))) -> 100 | L7: =IF($K6<=0,0,MAX(0,IF($B7="Travel",Parameters!$B$13*7,IF($B7="Work",Parameters!$B$14,0))-(SUM(D6:J6)-SUM(D7:J7)))) -> 0 | M7: =IF(K7<=0,"RUN OVER","alive") -> alive | O7: Vitality remaining | P7: =K51 -> 0
A8: 2 | B8: Work | C8: 7 | D8: =IF($K7<=0,D7,IF($B8="Travel",MAX(0,D7-Parameters!$B$13),IF(AND($B8="Work",$C8=1),MAX(0,D7-Parameters!$B$14),IF(AND($B8="Gather",$C8=1),MIN(Parameters!$B$10,D7+Parameters!$B$16),D7)))) -> 85 | E8: =IF($K7<=0,E7,IF($B8="Travel",MAX(0,E7-Parameters!$B$13),IF(AND($B8="Work",$C8=2),MAX(0,E7-Parameters!$B$14),IF(AND($B8="Gather",$C8=2),MIN(Parameters!$B$10,E7+Parameters!$B$16),E7)))) -> 85 | F8: =IF($K7<=0,F7,IF($B8="Travel",MAX(0,F7-Parameters!$B$13),IF(AND($B8="Work",$C8=3),MAX(0,F7-Parameters!$B$14),IF(AND($B8="Gather",$C8=3),MIN(Parameters!$B$10,F7+Parameters!$B$16),F7)))) -> 85 | G8: =IF($K7<=0,G7,IF($B8="Travel",MAX(0,G7-Parameters!$B$13),IF(AND($B8="Work",$C8=4),MAX(0,G7-Parameters!$B$14),IF(AND($B8="Gather",$C8=4),MIN(Parameters!$B$10,G7+Parameters!$B$16),G7)))) -> 85 | H8: =IF($K7<=0,H7,IF($B8="Travel",MAX(0,H7-Parameters!$B$13),IF(AND($B8="Work",$C8=5),MAX(0,H7-Parameters!$B$14),IF(AND($B8="Gather",$C8=5),MIN(Parameters!$B$10,H7+Parameters!$B$16),H7)))) -> 85 | I8: =IF($K7<=0,I7,IF($B8="Travel",MAX(0,I7-Parameters!$B$13),IF(AND($B8="Work",$C8=6),MAX(0,I7-Parameters!$B$14),IF(AND($B8="Gather",$C8=6),MIN(Parameters!$B$10,I7+Parameters!$B$16),I7)))) -> 85 | J8: =IF($K7<=0,J7,IF($B8="Travel",MAX(0,J7-Parameters!$B$13),IF(AND($B8="Work",$C8=7),MAX(0,J7-Parameters!$B$14),IF(AND($B8="Gather",$C8=7),MIN(Parameters!$B$10,J7+Parameters!$B$16),J7)))) -> 77 | K8: =IF($K7<=0,0,MAX(0,K7-L8*Parameters!$B$6-IF($B8="Gather",Parameters!$B$17,0))) -> 100 | L8: =IF($K7<=0,0,MAX(0,IF($B8="Travel",Parameters!$B$13*7,IF($B8="Work",Parameters!$B$14,0))-(SUM(D7:J7)-SUM(D8:J8)))) -> 0 | M8: =IF(K8<=0,"RUN OVER","alive") -> alive | O8: Traversals made | P8: =COUNTIFS(B7:B51,"Travel",M7:M51,"alive") -> 3
A9: 3 | B9: Work | C9: 7 | D9: =IF($K8<=0,D8,IF($B9="Travel",MAX(0,D8-Parameters!$B$13),IF(AND($B9="Work",$C9=1),MAX(0,D8-Parameters!$B$14),IF(AND($B9="Gather",$C9=1),MIN(Parameters!$B$10,D8+Parameters!$B$16),D8)))) -> 85 | E9: =IF($K8<=0,E8,IF($B9="Travel",MAX(0,E8-Parameters!$B$13),IF(AND($B9="Work",$C9=2),MAX(0,E8-Parameters!$B$14),IF(AND($B9="Gather",$C9=2),MIN(Parameters!$B$10,E8+Parameters!$B$16),E8)))) -> 85 | F9: =IF($K8<=0,F8,IF($B9="Travel",MAX(0,F8-Parameters!$B$13),IF(AND($B9="Work",$C9=3),MAX(0,F8-Parameters!$B$14),IF(AND($B9="Gather",$C9=3),MIN(Parameters!$B$10,F8+Parameters!$B$16),F8)))) -> 85 | G9: =IF($K8<=0,G8,IF($B9="Travel",MAX(0,G8-Parameters!$B$13),IF(AND($B9="Work",$C9=4),MAX(0,G8-Parameters!$B$14),IF(AND($B9="Gather",$C9=4),MIN(Parameters!$B$10,G8+Parameters!$B$16),G8)))) -> 85 | H9: =IF($K8<=0,H8,IF($B9="Travel",MAX(0,H8-Parameters!$B$13),IF(AND($B9="Work",$C9=5),MAX(0,H8-Parameters!$B$14),IF(AND($B9="Gather",$C9=5),MIN(Parameters!$B$10,H8+Parameters!$B$16),H8)))) -> 85 | I9: =IF($K8<=0,I8,IF($B9="Travel",MAX(0,I8-Parameters!$B$13),IF(AND($B9="Work",$C9=6),MAX(0,I8-Parameters!$B$14),IF(AND($B9="Gather",$C9=6),MIN(Parameters!$B$10,I8+Parameters!$B$16),I8)))) -> 85 | J9: =IF($K8<=0,J8,IF($B9="Travel",MAX(0,J8-Parameters!$B$13),IF(AND($B9="Work",$C9=7),MAX(0,J8-Parameters!$B$14),IF(AND($B9="Gather",$C9=7),MIN(Parameters!$B$10,J8+Parameters!$B$16),J8)))) -> 69 | K9: =IF($K8<=0,0,MAX(0,K8-L9*Parameters!$B$6-IF($B9="Gather",Parameters!$B$17,0))) -> 100 | L9: =IF($K8<=0,0,MAX(0,IF($B9="Travel",Parameters!$B$13*7,IF($B9="Work",Parameters!$B$14,0))-(SUM(D8:J8)-SUM(D9:J9)))) -> 0 | M9: =IF(K9<=0,"RUN OVER","alive") -> alive | O9: Workings cast | P9: =COUNTIFS(B7:B51,"Work",M7:M51,"alive") -> 28
A10: 4 | B10: Work | C10: 7 | D10: =IF($K9<=0,D9,IF($B10="Travel",MAX(0,D9-Parameters!$B$13),IF(AND($B10="Work",$C10=1),MAX(0,D9-Parameters!$B$14),IF(AND($B10="Gather",$C10=1),MIN(Parameters!$B$10,D9+Parameters!$B$16),D9)))) -> 85 | E10: =IF($K9<=0,E9,IF($B10="Travel",MAX(0,E9-Parameters!$B$13),IF(AND($B10="Work",$C10=2),MAX(0,E9-Parameters!$B$14),IF(AND($B10="Gather",$C10=2),MIN(Parameters!$B$10,E9+Parameters!$B$16),E9)))) -> 85 | F10: =IF($K9<=0,F9,IF($B10="Travel",MAX(0,F9-Parameters!$B$13),IF(AND($B10="Work",$C10=3),MAX(0,F9-Parameters!$B$14),IF(AND($B10="Gather",$C10=3),MIN(Parameters!$B$10,F9+Parameters!$B$16),F9)))) -> 85 | G10: =IF($K9<=0,G9,IF($B10="Travel",MAX(0,G9-Parameters!$B$13),IF(AND($B10="Work",$C10=4),MAX(0,G9-Parameters!$B$14),IF(AND($B10="Gather",$C10=4),MIN(Parameters!$B$10,G9+Parameters!$B$16),G9)))) -> 85 | H10: =IF($K9<=0,H9,IF($B10="Travel",MAX(0,H9-Parameters!$B$13),IF(AND($B10="Work",$C10=5),MAX(0,H9-Parameters!$B$14),IF(AND($B10="Gather",$C10=5),MIN(Parameters!$B$10,H9+Parameters!$B$16),H9)))) -> 85 | I10: =IF($K9<=0,I9,IF($B10="Travel",MAX(0,I9-Parameters!$B$13),IF(AND($B10="Work",$C10=6),MAX(0,I9-Parameters!$B$14),IF(AND($B10="Gather",$C10=6),MIN(Parameters!$B$10,I9+Parameters!$B$16),I9)))) -> 85 | J10: =IF($K9<=0,J9,IF($B10="Travel",MAX(0,J9-Parameters!$B$13),IF(AND($B10="Work",$C10=7),MAX(0,J9-Parameters!$B$14),IF(AND($B10="Gather",$C10=7),MIN(Parameters!$B$10,J9+Parameters!$B$16),J9)))) -> 61 | K10: =IF($K9<=0,0,MAX(0,K9-L10*Parameters!$B$6-IF($B10="Gather",Parameters!$B$17,0))) -> 100 | L10: =IF($K9<=0,0,MAX(0,IF($B10="Travel",Parameters!$B$13*7,IF($B10="Work",Parameters!$B$14,0))-(SUM(D9:J9)-SUM(D10:J10)))) -> 0 | M10: =IF(K10<=0,"RUN OVER","alive") -> alive | O10: Total overflow to vitality | P10: =SUM(L7:L51) -> 104
A11: 5 | B11: Work | C11: 7 | D11: =IF($K10<=0,D10,IF($B11="Travel",MAX(0,D10-Parameters!$B$13),IF(AND($B11="Work",$C11=1),MAX(0,D10-Parameters!$B$14),IF(AND($B11="Gather",$C11=1),MIN(Parameters!$B$10,D10+Parameters!$B$16),D10)))) -> 85 | E11: =IF($K10<=0,E10,IF($B11="Travel",MAX(0,E10-Parameters!$B$13),IF(AND($B11="Work",$C11=2),MAX(0,E10-Parameters!$B$14),IF(AND($B11="Gather",$C11=2),MIN(Parameters!$B$10,E10+Parameters!$B$16),E10)))) -> 85 | F11: =IF($K10<=0,F10,IF($B11="Travel",MAX(0,F10-Parameters!$B$13),IF(AND($B11="Work",$C11=3),MAX(0,F10-Parameters!$B$14),IF(AND($B11="Gather",$C11=3),MIN(Parameters!$B$10,F10+Parameters!$B$16),F10)))) -> 85 | G11: =IF($K10<=0,G10,IF($B11="Travel",MAX(0,G10-Parameters!$B$13),IF(AND($B11="Work",$C11=4),MAX(0,G10-Parameters!$B$14),IF(AND($B11="Gather",$C11=4),MIN(Parameters!$B$10,G10+Parameters!$B$16),G10)))) -> 85 | H11: =IF($K10<=0,H10,IF($B11="Travel",MAX(0,H10-Parameters!$B$13),IF(AND($B11="Work",$C11=5),MAX(0,H10-Parameters!$B$14),IF(AND($B11="Gather",$C11=5),MIN(Parameters!$B$10,H10+Parameters!$B$16),H10)))) -> 85 | I11: =IF($K10<=0,I10,IF($B11="Travel",MAX(0,I10-Parameters!$B$13),IF(AND($B11="Work",$C11=6),MAX(0,I10-Parameters!$B$14),IF(AND($B11="Gather",$C11=6),MIN(Parameters!$B$10,I10+Parameters!$B$16),I10)))) -> 85 | J11: =IF($K10<=0,J10,IF($B11="Travel",MAX(0,J10-Parameters!$B$13),IF(AND($B11="Work",$C11=7),MAX(0,J10-Parameters!$B$14),IF(AND($B11="Gather",$C11=7),MIN(Parameters!$B$10,J10+Parameters!$B$16),J10)))) -> 53 | K11: =IF($K10<=0,0,MAX(0,K10-L11*Parameters!$B$6-IF($B11="Gather",Parameters!$B$17,0))) -> 100 | L11: =IF($K10<=0,0,MAX(0,IF($B11="Travel",Parameters!$B$13*7,IF($B11="Work",Parameters!$B$14,0))-(SUM(D10:J10)-SUM(D11:J11)))) -> 0 | M11: =IF(K11<=0,"RUN OVER","alive") -> alive | O11: Run length (minutes) | P11: =IFERROR(P6*Parameters!$B$20/60,0) -> 2.2
A12: 6 | B12: Work | C12: 7 | D12: =IF($K11<=0,D11,IF($B12="Travel",MAX(0,D11-Parameters!$B$13),IF(AND($B12="Work",$C12=1),MAX(0,D11-Parameters!$B$14),IF(AND($B12="Gather",$C12=1),MIN(Parameters!$B$10,D11+Parameters!$B$16),D11)))) -> 85 | E12: =IF($K11<=0,E11,IF($B12="Travel",MAX(0,E11-Parameters!$B$13),IF(AND($B12="Work",$C12=2),MAX(0,E11-Parameters!$B$14),IF(AND($B12="Gather",$C12=2),MIN(Parameters!$B$10,E11+Parameters!$B$16),E11)))) -> 85 | F12: =IF($K11<=0,F11,IF($B12="Travel",MAX(0,F11-Parameters!$B$13),IF(AND($B12="Work",$C12=3),MAX(0,F11-Parameters!$B$14),IF(AND($B12="Gather",$C12=3),MIN(Parameters!$B$10,F11+Parameters!$B$16),F11)))) -> 85 | G12: =IF($K11<=0,G11,IF($B12="Travel",MAX(0,G11-Parameters!$B$13),IF(AND($B12="Work",$C12=4),MAX(0,G11-Parameters!$B$14),IF(AND($B12="Gather",$C12=4),MIN(Parameters!$B$10,G11+Parameters!$B$16),G11)))) -> 85 | H12: =IF($K11<=0,H11,IF($B12="Travel",MAX(0,H11-Parameters!$B$13),IF(AND($B12="Work",$C12=5),MAX(0,H11-Parameters!$B$14),IF(AND($B12="Gather",$C12=5),MIN(Parameters!$B$10,H11+Parameters!$B$16),H11)))) -> 85 | I12: =IF($K11<=0,I11,IF($B12="Travel",MAX(0,I11-Parameters!$B$13),IF(AND($B12="Work",$C12=6),MAX(0,I11-Parameters!$B$14),IF(AND($B12="Gather",$C12=6),MIN(Parameters!$B$10,I11+Parameters!$B$16),I11)))) -> 85 | J12: =IF($K11<=0,J11,IF($B12="Travel",MAX(0,J11-Parameters!$B$13),IF(AND($B12="Work",$C12=7),MAX(0,J11-Parameters!$B$14),IF(AND($B12="Gather",$C12=7),MIN(Parameters!$B$10,J11+Parameters!$B$16),J11)))) -> 45 | K12: =IF($K11<=0,0,MAX(0,K11-L12*Parameters!$B$6-IF($B12="Gather",Parameters!$B$17,0))) -> 100 | L12: =IF($K11<=0,0,MAX(0,IF($B12="Travel",Parameters!$B$13*7,IF($B12="Work",Parameters!$B$14,0))-(SUM(D11:J11)-SUM(D12:J12)))) -> 0 | M12: =IF(K12<=0,"RUN OVER","alive") -> alive
A13: 7 | B13: Work | C13: 7 | D13: =IF($K12<=0,D12,IF($B13="Travel",MAX(0,D12-Parameters!$B$13),IF(AND($B13="Work",$C13=1),MAX(0,D12-Parameters!$B$14),IF(AND($B13="Gather",$C13=1),MIN(Parameters!$B$10,D12+Parameters!$B$16),D12)))) -> 85 | E13: =IF($K12<=0,E12,IF($B13="Travel",MAX(0,E12-Parameters!$B$13),IF(AND($B13="Work",$C13=2),MAX(0,E12-Parameters!$B$14),IF(AND($B13="Gather",$C13=2),MIN(Parameters!$B$10,E12+Parameters!$B$16),E12)))) -> 85 | F13: =IF($K12<=0,F12,IF($B13="Travel",MAX(0,F12-Parameters!$B$13),IF(AND($B13="Work",$C13=3),MAX(0,F12-Parameters!$B$14),IF(AND($B13="Gather",$C13=3),MIN(Parameters!$B$10,F12+Parameters!$B$16),F12)))) -> 85 | G13: =IF($K12<=0,G12,IF($B13="Travel",MAX(0,G12-Parameters!$B$13),IF(AND($B13="Work",$C13=4),MAX(0,G12-Parameters!$B$14),IF(AND($B13="Gather",$C13=4),MIN(Parameters!$B$10,G12+Parameters!$B$16),G12)))) -> 85 | H13: =IF($K12<=0,H12,IF($B13="Travel",MAX(0,H12-Parameters!$B$13),IF(AND($B13="Work",$C13=5),MAX(0,H12-Parameters!$B$14),IF(AND($B13="Gather",$C13=5),MIN(Parameters!$B$10,H12+Parameters!$B$16),H12)))) -> 85 | I13: =IF($K12<=0,I12,IF($B13="Travel",MAX(0,I12-Parameters!$B$13),IF(AND($B13="Work",$C13=6),MAX(0,I12-Parameters!$B$14),IF(AND($B13="Gather",$C13=6),MIN(Parameters!$B$10,I12+Parameters!$B$16),I12)))) -> 85 | J13: =IF($K12<=0,J12,IF($B13="Travel",MAX(0,J12-Parameters!$B$13),IF(AND($B13="Work",$C13=7),MAX(0,J12-Parameters!$B$14),IF(AND($B13="Gather",$C13=7),MIN(Parameters!$B$10,J12+Parameters!$B$16),J12)))) -> 37 | K13: =IF($K12<=0,0,MAX(0,K12-L13*Parameters!$B$6-IF($B13="Gather",Parameters!$B$17,0))) -> 100 | L13: =IF($K12<=0,0,MAX(0,IF($B13="Travel",Parameters!$B$13*7,IF($B13="Work",Parameters!$B$14,0))-(SUM(D12:J12)-SUM(D13:J13)))) -> 0 | M13: =IF(K13<=0,"RUN OVER","alive") -> alive | O13: Edit column B and C to test a route.
A14: 8 | B14: Work | C14: 7 | D14: =IF($K13<=0,D13,IF($B14="Travel",MAX(0,D13-Parameters!$B$13),IF(AND($B14="Work",$C14=1),MAX(0,D13-Parameters!$B$14),IF(AND($B14="Gather",$C14=1),MIN(Parameters!$B$10,D13+Parameters!$B$16),D13)))) -> 85 | E14: =IF($K13<=0,E13,IF($B14="Travel",MAX(0,E13-Parameters!$B$13),IF(AND($B14="Work",$C14=2),MAX(0,E13-Parameters!$B$14),IF(AND($B14="Gather",$C14=2),MIN(Parameters!$B$10,E13+Parameters!$B$16),E13)))) -> 85 | F14: =IF($K13<=0,F13,IF($B14="Travel",MAX(0,F13-Parameters!$B$13),IF(AND($B14="Work",$C14=3),MAX(0,F13-Parameters!$B$14),IF(AND($B14="Gather",$C14=3),MIN(Parameters!$B$10,F13+Parameters!$B$16),F13)))) -> 85 | G14: =IF($K13<=0,G13,IF($B14="Travel",MAX(0,G13-Parameters!$B$13),IF(AND($B14="Work",$C14=4),MAX(0,G13-Parameters!$B$14),IF(AND($B14="Gather",$C14=4),MIN(Parameters!$B$10,G13+Parameters!$B$16),G13)))) -> 85 | H14: =IF($K13<=0,H13,IF($B14="Travel",MAX(0,H13-Parameters!$B$13),IF(AND($B14="Work",$C14=5),MAX(0,H13-Parameters!$B$14),IF(AND($B14="Gather",$C14=5),MIN(Parameters!$B$10,H13+Parameters!$B$16),H13)))) -> 85 | I14: =IF($K13<=0,I13,IF($B14="Travel",MAX(0,I13-Parameters!$B$13),IF(AND($B14="Work",$C14=6),MAX(0,I13-Parameters!$B$14),IF(AND($B14="Gather",$C14=6),MIN(Parameters!$B$10,I13+Parameters!$B$16),I13)))) -> 85 | J14: =IF($K13<=0,J13,IF($B14="Travel",MAX(0,J13-Parameters!$B$13),IF(AND($B14="Work",$C14=7),MAX(0,J13-Parameters!$B$14),IF(AND($B14="Gather",$C14=7),MIN(Parameters!$B$10,J13+Parameters!$B$16),J13)))) -> 29 | K14: =IF($K13<=0,0,MAX(0,K13-L14*Parameters!$B$6-IF($B14="Gather",Parameters!$B$17,0))) -> 100 | L14: =IF($K13<=0,0,MAX(0,IF($B14="Travel",Parameters!$B$13*7,IF($B14="Work",Parameters!$B$14,0))-(SUM(D13:J13)-SUM(D14:J14)))) -> 0 | M14: =IF(K14<=0,"RUN OVER","alive") -> alive | O14: Actions after RUN OVER are not counted.
A15: 9 | B15: Work | C15: 7 | D15: =IF($K14<=0,D14,IF($B15="Travel",MAX(0,D14-Parameters!$B$13),IF(AND($B15="Work",$C15=1),MAX(0,D14-Parameters!$B$14),IF(AND($B15="Gather",$C15=1),MIN(Parameters!$B$10,D14+Parameters!$B$16),D14)))) -> 85 | E15: =IF($K14<=0,E14,IF($B15="Travel",MAX(0,E14-Parameters!$B$13),IF(AND($B15="Work",$C15=2),MAX(0,E14-Parameters!$B$14),IF(AND($B15="Gather",$C15=2),MIN(Parameters!$B$10,E14+Parameters!$B$16),E14)))) -> 85 | F15: =IF($K14<=0,F14,IF($B15="Travel",MAX(0,F14-Parameters!$B$13),IF(AND($B15="Work",$C15=3),MAX(0,F14-Parameters!$B$14),IF(AND($B15="Gather",$C15=3),MIN(Parameters!$B$10,F14+Parameters!$B$16),F14)))) -> 85 | G15: =IF($K14<=0,G14,IF($B15="Travel",MAX(0,G14-Parameters!$B$13),IF(AND($B15="Work",$C15=4),MAX(0,G14-Parameters!$B$14),IF(AND($B15="Gather",$C15=4),MIN(Parameters!$B$10,G14+Parameters!$B$16),G14)))) -> 85 | H15: =IF($K14<=0,H14,IF($B15="Travel",MAX(0,H14-Parameters!$B$13),IF(AND($B15="Work",$C15=5),MAX(0,H14-Parameters!$B$14),IF(AND($B15="Gather",$C15=5),MIN(Parameters!$B$10,H14+Parameters!$B$16),H14)))) -> 85 | I15: =IF($K14<=0,I14,IF($B15="Travel",MAX(0,I14-Parameters!$B$13),IF(AND($B15="Work",$C15=6),MAX(0,I14-Parameters!$B$14),IF(AND($B15="Gather",$C15=6),MIN(Parameters!$B$10,I14+Parameters!$B$16),I14)))) -> 85 | J15: =IF($K14<=0,J14,IF($B15="Travel",MAX(0,J14-Parameters!$B$13),IF(AND($B15="Work",$C15=7),MAX(0,J14-Parameters!$B$14),IF(AND($B15="Gather",$C15=7),MIN(Parameters!$B$10,J14+Parameters!$B$16),J14)))) -> 21 | K15: =IF($K14<=0,0,MAX(0,K14-L15*Parameters!$B$6-IF($B15="Gather",Parameters!$B$17,0))) -> 100 | L15: =IF($K14<=0,0,MAX(0,IF($B15="Travel",Parameters!$B$13*7,IF($B15="Work",Parameters!$B$14,0))-(SUM(D14:J14)-SUM(D15:J15)))) -> 0 | M15: =IF(K15<=0,"RUN OVER","alive") -> alive
A16: 10 | B16: Work | C16: 7 | D16: =IF($K15<=0,D15,IF($B16="Travel",MAX(0,D15-Parameters!$B$13),IF(AND($B16="Work",$C16=1),MAX(0,D15-Parameters!$B$14),IF(AND($B16="Gather",$C16=1),MIN(Parameters!$B$10,D15+Parameters!$B$16),D15)))) -> 85 | E16: =IF($K15<=0,E15,IF($B16="Travel",MAX(0,E15-Parameters!$B$13),IF(AND($B16="Work",$C16=2),MAX(0,E15-Parameters!$B$14),IF(AND($B16="Gather",$C16=2),MIN(Parameters!$B$10,E15+Parameters!$B$16),E15)))) -> 85 | F16: =IF($K15<=0,F15,IF($B16="Travel",MAX(0,F15-Parameters!$B$13),IF(AND($B16="Work",$C16=3),MAX(0,F15-Parameters!$B$14),IF(AND($B16="Gather",$C16=3),MIN(Parameters!$B$10,F15+Parameters!$B$16),F15)))) -> 85 | G16: =IF($K15<=0,G15,IF($B16="Travel",MAX(0,G15-Parameters!$B$13),IF(AND($B16="Work",$C16=4),MAX(0,G15-Parameters!$B$14),IF(AND($B16="Gather",$C16=4),MIN(Parameters!$B$10,G15+Parameters!$B$16),G15)))) -> 85 | H16: =IF($K15<=0,H15,IF($B16="Travel",MAX(0,H15-Parameters!$B$13),IF(AND($B16="Work",$C16=5),MAX(0,H15-Parameters!$B$14),IF(AND($B16="Gather",$C16=5),MIN(Parameters!$B$10,H15+Parameters!$B$16),H15)))) -> 85 | I16: =IF($K15<=0,I15,IF($B16="Travel",MAX(0,I15-Parameters!$B$13),IF(AND($B16="Work",$C16=6),MAX(0,I15-Parameters!$B$14),IF(AND($B16="Gather",$C16=6),MIN(Parameters!$B$10,I15+Parameters!$B$16),I15)))) -> 85 | J16: =IF($K15<=0,J15,IF($B16="Travel",MAX(0,J15-Parameters!$B$13),IF(AND($B16="Work",$C16=7),MAX(0,J15-Parameters!$B$14),IF(AND($B16="Gather",$C16=7),MIN(Parameters!$B$10,J15+Parameters!$B$16),J15)))) -> 13 | K16: =IF($K15<=0,0,MAX(0,K15-L16*Parameters!$B$6-IF($B16="Gather",Parameters!$B$17,0))) -> 100 | L16: =IF($K15<=0,0,MAX(0,IF($B16="Travel",Parameters!$B$13*7,IF($B16="Work",Parameters!$B$14,0))-(SUM(D15:J15)-SUM(D16:J16)))) -> 0 | M16: =IF(K16<=0,"RUN OVER","alive") -> alive
A17: 11 | B17: Work | C17: 7 | D17: =IF($K16<=0,D16,IF($B17="Travel",MAX(0,D16-Parameters!$B$13),IF(AND($B17="Work",$C17=1),MAX(0,D16-Parameters!$B$14),IF(AND($B17="Gather",$C17=1),MIN(Parameters!$B$10,D16+Parameters!$B$16),D16)))) -> 85 | E17: =IF($K16<=0,E16,IF($B17="Travel",MAX(0,E16-Parameters!$B$13),IF(AND($B17="Work",$C17=2),MAX(0,E16-Parameters!$B$14),IF(AND($B17="Gather",$C17=2),MIN(Parameters!$B$10,E16+Parameters!$B$16),E16)))) -> 85 | F17: =IF($K16<=0,F16,IF($B17="Travel",MAX(0,F16-Parameters!$B$13),IF(AND($B17="Work",$C17=3),MAX(0,F16-Parameters!$B$14),IF(AND($B17="Gather",$C17=3),MIN(Parameters!$B$10,F16+Parameters!$B$16),F16)))) -> 85 | G17: =IF($K16<=0,G16,IF($B17="Travel",MAX(0,G16-Parameters!$B$13),IF(AND($B17="Work",$C17=4),MAX(0,G16-Parameters!$B$14),IF(AND($B17="Gather",$C17=4),MIN(Parameters!$B$10,G16+Parameters!$B$16),G16)))) -> 85 | H17: =IF($K16<=0,H16,IF($B17="Travel",MAX(0,H16-Parameters!$B$13),IF(AND($B17="Work",$C17=5),MAX(0,H16-Parameters!$B$14),IF(AND($B17="Gather",$C17=5),MIN(Parameters!$B$10,H16+Parameters!$B$16),H16)))) -> 85 | I17: =IF($K16<=0,I16,IF($B17="Travel",MAX(0,I16-Parameters!$B$13),IF(AND($B17="Work",$C17=6),MAX(0,I16-Parameters!$B$14),IF(AND($B17="Gather",$C17=6),MIN(Parameters!$B$10,I16+Parameters!$B$16),I16)))) -> 85 | J17: =IF($K16<=0,J16,IF($B17="Travel",MAX(0,J16-Parameters!$B$13),IF(AND($B17="Work",$C17=7),MAX(0,J16-Parameters!$B$14),IF(AND($B17="Gather",$C17=7),MIN(Parameters!$B$10,J16+Parameters!$B$16),J16)))) -> 5 | K17: =IF($K16<=0,0,MAX(0,K16-L17*Parameters!$B$6-IF($B17="Gather",Parameters!$B$17,0))) -> 100 | L17: =IF($K16<=0,0,MAX(0,IF($B17="Travel",Parameters!$B$13*7,IF($B17="Work",Parameters!$B$14,0))-(SUM(D16:J16)-SUM(D17:J17)))) -> 0 | M17: =IF(K17<=0,"RUN OVER","alive") -> alive
A18: 12 | B18: Work | C18: 7 | D18: =IF($K17<=0,D17,IF($B18="Travel",MAX(0,D17-Parameters!$B$13),IF(AND($B18="Work",$C18=1),MAX(0,D17-Parameters!$B$14),IF(AND($B18="Gather",$C18=1),MIN(Parameters!$B$10,D17+Parameters!$B$16),D17)))) -> 85 | E18: =IF($K17<=0,E17,IF($B18="Travel",MAX(0,E17-Parameters!$B$13),IF(AND($B18="Work",$C18=2),MAX(0,E17-Parameters!$B$14),IF(AND($B18="Gather",$C18=2),MIN(Parameters!$B$10,E17+Parameters!$B$16),E17)))) -> 85 | F18: =IF($K17<=0,F17,IF($B18="Travel",MAX(0,F17-Parameters!$B$13),IF(AND($B18="Work",$C18=3),MAX(0,F17-Parameters!$B$14),IF(AND($B18="Gather",$C18=3),MIN(Parameters!$B$10,F17+Parameters!$B$16),F17)))) -> 85 | G18: =IF($K17<=0,G17,IF($B18="Travel",MAX(0,G17-Parameters!$B$13),IF(AND($B18="Work",$C18=4),MAX(0,G17-Parameters!$B$14),IF(AND($B18="Gather",$C18=4),MIN(Parameters!$B$10,G17+Parameters!$B$16),G17)))) -> 85 | H18: =IF($K17<=0,H17,IF($B18="Travel",MAX(0,H17-Parameters!$B$13),IF(AND($B18="Work",$C18=5),MAX(0,H17-Parameters!$B$14),IF(AND($B18="Gather",$C18=5),MIN(Parameters!$B$10,H17+Parameters!$B$16),H17)))) -> 85 | I18: =IF($K17<=0,I17,IF($B18="Travel",MAX(0,I17-Parameters!$B$13),IF(AND($B18="Work",$C18=6),MAX(0,I17-Parameters!$B$14),IF(AND($B18="Gather",$C18=6),MIN(Parameters!$B$10,I17+Parameters!$B$16),I17)))) -> 85 | J18: =IF($K17<=0,J17,IF($B18="Travel",MAX(0,J17-Parameters!$B$13),IF(AND($B18="Work",$C18=7),MAX(0,J17-Parameters!$B$14),IF(AND($B18="Gather",$C18=7),MIN(Parameters!$B$10,J17+Parameters!$B$16),J17)))) -> 0 | K18: =IF($K17<=0,0,MAX(0,K17-L18*Parameters!$B$6-IF($B18="Gather",Parameters!$B$17,0))) -> 97 | L18: =IF($K17<=0,0,MAX(0,IF($B18="Travel",Parameters!$B$13*7,IF($B18="Work",Parameters!$B$14,0))-(SUM(D17:J17)-SUM(D18:J18)))) -> 3 | M18: =IF(K18<=0,"RUN OVER","alive") -> alive
A19: 13 | B19: Work | C19: 7 | D19: =IF($K18<=0,D18,IF($B19="Travel",MAX(0,D18-Parameters!$B$13),IF(AND($B19="Work",$C19=1),MAX(0,D18-Parameters!$B$14),IF(AND($B19="Gather",$C19=1),MIN(Parameters!$B$10,D18+Parameters!$B$16),D18)))) -> 85 | E19: =IF($K18<=0,E18,IF($B19="Travel",MAX(0,E18-Parameters!$B$13),IF(AND($B19="Work",$C19=2),MAX(0,E18-Parameters!$B$14),IF(AND($B19="Gather",$C19=2),MIN(Parameters!$B$10,E18+Parameters!$B$16),E18)))) -> 85 | F19: =IF($K18<=0,F18,IF($B19="Travel",MAX(0,F18-Parameters!$B$13),IF(AND($B19="Work",$C19=3),MAX(0,F18-Parameters!$B$14),IF(AND($B19="Gather",$C19=3),MIN(Parameters!$B$10,F18+Parameters!$B$16),F18)))) -> 85 | G19: =IF($K18<=0,G18,IF($B19="Travel",MAX(0,G18-Parameters!$B$13),IF(AND($B19="Work",$C19=4),MAX(0,G18-Parameters!$B$14),IF(AND($B19="Gather",$C19=4),MIN(Parameters!$B$10,G18+Parameters!$B$16),G18)))) -> 85 | H19: =IF($K18<=0,H18,IF($B19="Travel",MAX(0,H18-Parameters!$B$13),IF(AND($B19="Work",$C19=5),MAX(0,H18-Parameters!$B$14),IF(AND($B19="Gather",$C19=5),MIN(Parameters!$B$10,H18+Parameters!$B$16),H18)))) -> 85 | I19: =IF($K18<=0,I18,IF($B19="Travel",MAX(0,I18-Parameters!$B$13),IF(AND($B19="Work",$C19=6),MAX(0,I18-Parameters!$B$14),IF(AND($B19="Gather",$C19=6),MIN(Parameters!$B$10,I18+Parameters!$B$16),I18)))) -> 85 | J19: =IF($K18<=0,J18,IF($B19="Travel",MAX(0,J18-Parameters!$B$13),IF(AND($B19="Work",$C19=7),MAX(0,J18-Parameters!$B$14),IF(AND($B19="Gather",$C19=7),MIN(Parameters!$B$10,J18+Parameters!$B$16),J18)))) -> 0 | K19: =IF($K18<=0,0,MAX(0,K18-L19*Parameters!$B$6-IF($B19="Gather",Parameters!$B$17,0))) -> 89 | L19: =IF($K18<=0,0,MAX(0,IF($B19="Travel",Parameters!$B$13*7,IF($B19="Work",Parameters!$B$14,0))-(SUM(D18:J18)-SUM(D19:J19)))) -> 8 | M19: =IF(K19<=0,"RUN OVER","alive") -> alive
A20: 14 | B20: Gather | C20: 7 | D20: =IF($K19<=0,D19,IF($B20="Travel",MAX(0,D19-Parameters!$B$13),IF(AND($B20="Work",$C20=1),MAX(0,D19-Parameters!$B$14),IF(AND($B20="Gather",$C20=1),MIN(Parameters!$B$10,D19+Parameters!$B$16),D19)))) -> 85 | E20: =IF($K19<=0,E19,IF($B20="Travel",MAX(0,E19-Parameters!$B$13),IF(AND($B20="Work",$C20=2),MAX(0,E19-Parameters!$B$14),IF(AND($B20="Gather",$C20=2),MIN(Parameters!$B$10,E19+Parameters!$B$16),E19)))) -> 85 | F20: =IF($K19<=0,F19,IF($B20="Travel",MAX(0,F19-Parameters!$B$13),IF(AND($B20="Work",$C20=3),MAX(0,F19-Parameters!$B$14),IF(AND($B20="Gather",$C20=3),MIN(Parameters!$B$10,F19+Parameters!$B$16),F19)))) -> 85 | G20: =IF($K19<=0,G19,IF($B20="Travel",MAX(0,G19-Parameters!$B$13),IF(AND($B20="Work",$C20=4),MAX(0,G19-Parameters!$B$14),IF(AND($B20="Gather",$C20=4),MIN(Parameters!$B$10,G19+Parameters!$B$16),G19)))) -> 85 | H20: =IF($K19<=0,H19,IF($B20="Travel",MAX(0,H19-Parameters!$B$13),IF(AND($B20="Work",$C20=5),MAX(0,H19-Parameters!$B$14),IF(AND($B20="Gather",$C20=5),MIN(Parameters!$B$10,H19+Parameters!$B$16),H19)))) -> 85 | I20: =IF($K19<=0,I19,IF($B20="Travel",MAX(0,I19-Parameters!$B$13),IF(AND($B20="Work",$C20=6),MAX(0,I19-Parameters!$B$14),IF(AND($B20="Gather",$C20=6),MIN(Parameters!$B$10,I19+Parameters!$B$16),I19)))) -> 85 | J20: =IF($K19<=0,J19,IF($B20="Travel",MAX(0,J19-Parameters!$B$13),IF(AND($B20="Work",$C20=7),MAX(0,J19-Parameters!$B$14),IF(AND($B20="Gather",$C20=7),MIN(Parameters!$B$10,J19+Parameters!$B$16),J19)))) -> 20 | K20: =IF($K19<=0,0,MAX(0,K19-L20*Parameters!$B$6-IF($B20="Gather",Parameters!$B$17,0))) -> 67 | L20: =IF($K19<=0,0,MAX(0,IF($B20="Travel",Parameters!$B$13*7,IF($B20="Work",Parameters!$B$14,0))-(SUM(D19:J19)-SUM(D20:J20)))) -> 20 | M20: =IF(K20<=0,"RUN OVER","alive") -> alive
A21: 15 | B21: Gather | C21: 7 | D21: =IF($K20<=0,D20,IF($B21="Travel",MAX(0,D20-Parameters!$B$13),IF(AND($B21="Work",$C21=1),MAX(0,D20-Parameters!$B$14),IF(AND($B21="Gather",$C21=1),MIN(Parameters!$B$10,D20+Parameters!$B$16),D20)))) -> 85 | E21: =IF($K20<=0,E20,IF($B21="Travel",MAX(0,E20-Parameters!$B$13),IF(AND($B21="Work",$C21=2),MAX(0,E20-Parameters!$B$14),IF(AND($B21="Gather",$C21=2),MIN(Parameters!$B$10,E20+Parameters!$B$16),E20)))) -> 85 | F21: =IF($K20<=0,F20,IF($B21="Travel",MAX(0,F20-Parameters!$B$13),IF(AND($B21="Work",$C21=3),MAX(0,F20-Parameters!$B$14),IF(AND($B21="Gather",$C21=3),MIN(Parameters!$B$10,F20+Parameters!$B$16),F20)))) -> 85 | G21: =IF($K20<=0,G20,IF($B21="Travel",MAX(0,G20-Parameters!$B$13),IF(AND($B21="Work",$C21=4),MAX(0,G20-Parameters!$B$14),IF(AND($B21="Gather",$C21=4),MIN(Parameters!$B$10,G20+Parameters!$B$16),G20)))) -> 85 | H21: =IF($K20<=0,H20,IF($B21="Travel",MAX(0,H20-Parameters!$B$13),IF(AND($B21="Work",$C21=5),MAX(0,H20-Parameters!$B$14),IF(AND($B21="Gather",$C21=5),MIN(Parameters!$B$10,H20+Parameters!$B$16),H20)))) -> 85 | I21: =IF($K20<=0,I20,IF($B21="Travel",MAX(0,I20-Parameters!$B$13),IF(AND($B21="Work",$C21=6),MAX(0,I20-Parameters!$B$14),IF(AND($B21="Gather",$C21=6),MIN(Parameters!$B$10,I20+Parameters!$B$16),I20)))) -> 85 | J21: =IF($K20<=0,J20,IF($B21="Travel",MAX(0,J20-Parameters!$B$13),IF(AND($B21="Work",$C21=7),MAX(0,J20-Parameters!$B$14),IF(AND($B21="Gather",$C21=7),MIN(Parameters!$B$10,J20+Parameters!$B$16),J20)))) -> 40 | K21: =IF($K20<=0,0,MAX(0,K20-L21*Parameters!$B$6-IF($B21="Gather",Parameters!$B$17,0))) -> 45 | L21: =IF($K20<=0,0,MAX(0,IF($B21="Travel",Parameters!$B$13*7,IF($B21="Work",Parameters!$B$14,0))-(SUM(D20:J20)-SUM(D21:J21)))) -> 20 | M21: =IF(K21<=0,"RUN OVER","alive") -> alive
A22: 16 | B22: Travel | D22: =IF($K21<=0,D21,IF($B22="Travel",MAX(0,D21-Parameters!$B$13),IF(AND($B22="Work",$C22=1),MAX(0,D21-Parameters!$B$14),IF(AND($B22="Gather",$C22=1),MIN(Parameters!$B$10,D21+Parameters!$B$16),D21)))) -> 70 | E22: =IF($K21<=0,E21,IF($B22="Travel",MAX(0,E21-Parameters!$B$13),IF(AND($B22="Work",$C22=2),MAX(0,E21-Parameters!$B$14),IF(AND($B22="Gather",$C22=2),MIN(Parameters!$B$10,E21+Parameters!$B$16),E21)))) -> 70 | F22: =IF($K21<=0,F21,IF($B22="Travel",MAX(0,F21-Parameters!$B$13),IF(AND($B22="Work",$C22=3),MAX(0,F21-Parameters!$B$14),IF(AND($B22="Gather",$C22=3),MIN(Parameters!$B$10,F21+Parameters!$B$16),F21)))) -> 70 | G22: =IF($K21<=0,G21,IF($B22="Travel",MAX(0,G21-Parameters!$B$13),IF(AND($B22="Work",$C22=4),MAX(0,G21-Parameters!$B$14),IF(AND($B22="Gather",$C22=4),MIN(Parameters!$B$10,G21+Parameters!$B$16),G21)))) -> 70 | H22: =IF($K21<=0,H21,IF($B22="Travel",MAX(0,H21-Parameters!$B$13),IF(AND($B22="Work",$C22=5),MAX(0,H21-Parameters!$B$14),IF(AND($B22="Gather",$C22=5),MIN(Parameters!$B$10,H21+Parameters!$B$16),H21)))) -> 70 | I22: =IF($K21<=0,I21,IF($B22="Travel",MAX(0,I21-Parameters!$B$13),IF(AND($B22="Work",$C22=6),MAX(0,I21-Parameters!$B$14),IF(AND($B22="Gather",$C22=6),MIN(Parameters!$B$10,I21+Parameters!$B$16),I21)))) -> 70 | J22: =IF($K21<=0,J21,IF($B22="Travel",MAX(0,J21-Parameters!$B$13),IF(AND($B22="Work",$C22=7),MAX(0,J21-Parameters!$B$14),IF(AND($B22="Gather",$C22=7),MIN(Parameters!$B$10,J21+Parameters!$B$16),J21)))) -> 25 | K22: =IF($K21<=0,0,MAX(0,K21-L22*Parameters!$B$6-IF($B22="Gather",Parameters!$B$17,0))) -> 45 | L22: =IF($K21<=0,0,MAX(0,IF($B22="Travel",Parameters!$B$13*7,IF($B22="Work",Parameters!$B$14,0))-(SUM(D21:J21)-SUM(D22:J22)))) -> 0 | M22: =IF(K22<=0,"RUN OVER","alive") -> alive
A23: 17 | B23: Work | C23: 1 | D23: =IF($K22<=0,D22,IF($B23="Travel",MAX(0,D22-Parameters!$B$13),IF(AND($B23="Work",$C23=1),MAX(0,D22-Parameters!$B$14),IF(AND($B23="Gather",$C23=1),MIN(Parameters!$B$10,D22+Parameters!$B$16),D22)))) -> 62 | E23: =IF($K22<=0,E22,IF($B23="Travel",MAX(0,E22-Parameters!$B$13),IF(AND($B23="Work",$C23=2),MAX(0,E22-Parameters!$B$14),IF(AND($B23="Gather",$C23=2),MIN(Parameters!$B$10,E22+Parameters!$B$16),E22)))) -> 70 | F23: =IF($K22<=0,F22,IF($B23="Travel",MAX(0,F22-Parameters!$B$13),IF(AND($B23="Work",$C23=3),MAX(0,F22-Parameters!$B$14),IF(AND($B23="Gather",$C23=3),MIN(Parameters!$B$10,F22+Parameters!$B$16),F22)))) -> 70 | G23: =IF($K22<=0,G22,IF($B23="Travel",MAX(0,G22-Parameters!$B$13),IF(AND($B23="Work",$C23=4),MAX(0,G22-Parameters!$B$14),IF(AND($B23="Gather",$C23=4),MIN(Parameters!$B$10,G22+Parameters!$B$16),G22)))) -> 70 | H23: =IF($K22<=0,H22,IF($B23="Travel",MAX(0,H22-Parameters!$B$13),IF(AND($B23="Work",$C23=5),MAX(0,H22-Parameters!$B$14),IF(AND($B23="Gather",$C23=5),MIN(Parameters!$B$10,H22+Parameters!$B$16),H22)))) -> 70 | I23: =IF($K22<=0,I22,IF($B23="Travel",MAX(0,I22-Parameters!$B$13),IF(AND($B23="Work",$C23=6),MAX(0,I22-Parameters!$B$14),IF(AND($B23="Gather",$C23=6),MIN(Parameters!$B$10,I22+Parameters!$B$16),I22)))) -> 70 | J23: =IF($K22<=0,J22,IF($B23="Travel",MAX(0,J22-Parameters!$B$13),IF(AND($B23="Work",$C23=7),MAX(0,J22-Parameters!$B$14),IF(AND($B23="Gather",$C23=7),MIN(Parameters!$B$10,J22+Parameters!$B$16),J22)))) -> 25 | K23: =IF($K22<=0,0,MAX(0,K22-L23*Parameters!$B$6-IF($B23="Gather",Parameters!$B$17,0))) -> 45 | L23: =IF($K22<=0,0,MAX(0,IF($B23="Travel",Parameters!$B$13*7,IF($B23="Work",Parameters!$B$14,0))-(SUM(D22:J22)-SUM(D23:J23)))) -> 0 | M23: =IF(K23<=0,"RUN OVER","alive") -> alive
A24: 18 | B24: Work | C24: 1 | D24: =IF($K23<=0,D23,IF($B24="Travel",MAX(0,D23-Parameters!$B$13),IF(AND($B24="Work",$C24=1),MAX(0,D23-Parameters!$B$14),IF(AND($B24="Gather",$C24=1),MIN(Parameters!$B$10,D23+Parameters!$B$16),D23)))) -> 54 | E24: =IF($K23<=0,E23,IF($B24="Travel",MAX(0,E23-Parameters!$B$13),IF(AND($B24="Work",$C24=2),MAX(0,E23-Parameters!$B$14),IF(AND($B24="Gather",$C24=2),MIN(Parameters!$B$10,E23+Parameters!$B$16),E23)))) -> 70 | F24: =IF($K23<=0,F23,IF($B24="Travel",MAX(0,F23-Parameters!$B$13),IF(AND($B24="Work",$C24=3),MAX(0,F23-Parameters!$B$14),IF(AND($B24="Gather",$C24=3),MIN(Parameters!$B$10,F23+Parameters!$B$16),F23)))) -> 70 | G24: =IF($K23<=0,G23,IF($B24="Travel",MAX(0,G23-Parameters!$B$13),IF(AND($B24="Work",$C24=4),MAX(0,G23-Parameters!$B$14),IF(AND($B24="Gather",$C24=4),MIN(Parameters!$B$10,G23+Parameters!$B$16),G23)))) -> 70 | H24: =IF($K23<=0,H23,IF($B24="Travel",MAX(0,H23-Parameters!$B$13),IF(AND($B24="Work",$C24=5),MAX(0,H23-Parameters!$B$14),IF(AND($B24="Gather",$C24=5),MIN(Parameters!$B$10,H23+Parameters!$B$16),H23)))) -> 70 | I24: =IF($K23<=0,I23,IF($B24="Travel",MAX(0,I23-Parameters!$B$13),IF(AND($B24="Work",$C24=6),MAX(0,I23-Parameters!$B$14),IF(AND($B24="Gather",$C24=6),MIN(Parameters!$B$10,I23+Parameters!$B$16),I23)))) -> 70 | J24: =IF($K23<=0,J23,IF($B24="Travel",MAX(0,J23-Parameters!$B$13),IF(AND($B24="Work",$C24=7),MAX(0,J23-Parameters!$B$14),IF(AND($B24="Gather",$C24=7),MIN(Parameters!$B$10,J23+Parameters!$B$16),J23)))) -> 25 | K24: =IF($K23<=0,0,MAX(0,K23-L24*Parameters!$B$6-IF($B24="Gather",Parameters!$B$17,0))) -> 45 | L24: =IF($K23<=0,0,MAX(0,IF($B24="Travel",Parameters!$B$13*7,IF($B24="Work",Parameters!$B$14,0))-(SUM(D23:J23)-SUM(D24:J24)))) -> 0 | M24: =IF(K24<=0,"RUN OVER","alive") -> alive
A25: 19 | B25: Work | C25: 1 | D25: =IF($K24<=0,D24,IF($B25="Travel",MAX(0,D24-Parameters!$B$13),IF(AND($B25="Work",$C25=1),MAX(0,D24-Parameters!$B$14),IF(AND($B25="Gather",$C25=1),MIN(Parameters!$B$10,D24+Parameters!$B$16),D24)))) -> 46 | E25: =IF($K24<=0,E24,IF($B25="Travel",MAX(0,E24-Parameters!$B$13),IF(AND($B25="Work",$C25=2),MAX(0,E24-Parameters!$B$14),IF(AND($B25="Gather",$C25=2),MIN(Parameters!$B$10,E24+Parameters!$B$16),E24)))) -> 70 | F25: =IF($K24<=0,F24,IF($B25="Travel",MAX(0,F24-Parameters!$B$13),IF(AND($B25="Work",$C25=3),MAX(0,F24-Parameters!$B$14),IF(AND($B25="Gather",$C25=3),MIN(Parameters!$B$10,F24+Parameters!$B$16),F24)))) -> 70 | G25: =IF($K24<=0,G24,IF($B25="Travel",MAX(0,G24-Parameters!$B$13),IF(AND($B25="Work",$C25=4),MAX(0,G24-Parameters!$B$14),IF(AND($B25="Gather",$C25=4),MIN(Parameters!$B$10,G24+Parameters!$B$16),G24)))) -> 70 | H25: =IF($K24<=0,H24,IF($B25="Travel",MAX(0,H24-Parameters!$B$13),IF(AND($B25="Work",$C25=5),MAX(0,H24-Parameters!$B$14),IF(AND($B25="Gather",$C25=5),MIN(Parameters!$B$10,H24+Parameters!$B$16),H24)))) -> 70 | I25: =IF($K24<=0,I24,IF($B25="Travel",MAX(0,I24-Parameters!$B$13),IF(AND($B25="Work",$C25=6),MAX(0,I24-Parameters!$B$14),IF(AND($B25="Gather",$C25=6),MIN(Parameters!$B$10,I24+Parameters!$B$16),I24)))) -> 70 | J25: =IF($K24<=0,J24,IF($B25="Travel",MAX(0,J24-Parameters!$B$13),IF(AND($B25="Work",$C25=7),MAX(0,J24-Parameters!$B$14),IF(AND($B25="Gather",$C25=7),MIN(Parameters!$B$10,J24+Parameters!$B$16),J24)))) -> 25 | K25: =IF($K24<=0,0,MAX(0,K24-L25*Parameters!$B$6-IF($B25="Gather",Parameters!$B$17,0))) -> 45 | L25: =IF($K24<=0,0,MAX(0,IF($B25="Travel",Parameters!$B$13*7,IF($B25="Work",Parameters!$B$14,0))-(SUM(D24:J24)-SUM(D25:J25)))) -> 0 | M25: =IF(K25<=0,"RUN OVER","alive") -> alive
